2025-03-26 10:46:28,009 : INFO : root : Loading config.
2025-03-26 10:46:28,020 : INFO : YamlMultifileConfigLoader : Machine config file #1: config.yaml
2025-03-26 10:46:28,020 : WARNING : ConfigProcessor : Config file in cache changed: C:\Users\homebrew\Desktop\thing_pinball\config\config.yaml
2025-03-26 10:46:28,020 : INFO : ConfigProcessor : Loading config from file C:\Users\homebrew\AppData\Local\Programs\Python\Python312\Lib\site-packages\mpf\mpfconfig.yaml.
2025-03-26 10:46:28,033 : INFO : ConfigProcessor : Loading config: C:\Users\homebrew\AppData\Local\Programs\Python\Python312\Lib\site-packages\mpf\mpfconfig.yaml
2025-03-26 10:46:28,033 : INFO : ConfigProcessor : Loading config from file C:\Users\homebrew\Desktop\thing_pinball\config\config.yaml.
2025-03-26 10:46:28,057 : INFO : ConfigProcessor : Loading config: C:\Users\homebrew\Desktop\thing_pinball\config\config.yaml
2025-03-26 10:46:28,057 : INFO : ConfigProcessor : Loading config: C:\Users\homebrew\Desktop\thing_pinball\config\service_mode.yaml
2025-03-26 10:46:28,057 : INFO : ConfigProcessor : Config file cache created: C:\Users\homebrew\AppData\Local\Temp\775282453bb9ae39cad69c39ab867a35.mpf_cache
2025-03-26 10:46:28,152 : INFO : ConfigProcessor : Loading config from cache: C:\Users\homebrew\AppData\Local\Temp\14eb6f99ffd433bf1b6bfef7e8b96202.mpf_cache
2025-03-26 10:46:28,159 : INFO : ConfigProcessor : Loading config from cache: C:\Users\homebrew\AppData\Local\Temp\3a13d33aed1669bafe3e56d7baff78a0.mpf_cache
2025-03-26 10:46:28,159 : INFO : ConfigProcessor : Loading config from cache: C:\Users\homebrew\AppData\Local\Temp\1352604168843921958881d1d8dd3c1b.mpf_cache
2025-03-26 10:46:28,159 : INFO : ConfigProcessor : Loading config from cache: C:\Users\homebrew\AppData\Local\Temp\14eb6f99ffd433bf1b6bfef7e8b96202.mpf_cache
2025-03-26 10:46:28,159 : INFO : ConfigProcessor : Loading config from cache: C:\Users\homebrew\AppData\Local\Temp\3a13d33aed1669bafe3e56d7baff78a0.mpf_cache
2025-03-26 10:46:28,159 : INFO : ConfigProcessor : Loading config from cache: C:\Users\homebrew\AppData\Local\Temp\82108c9d10735fbef5e8cced18b7d831.mpf_cache
2025-03-26 10:46:28,159 : INFO : ConfigProcessor : Loading config from cache: C:\Users\homebrew\AppData\Local\Temp\81d0f34cbd4c6d61cd4dad95e5100b6a.mpf_cache
2025-03-26 10:46:28,159 : INFO : ConfigProcessor : Loading config from cache: C:\Users\homebrew\AppData\Local\Temp\85b30d06c34a199299d858e267dca599.mpf_cache
2025-03-26 10:46:28,159 : INFO : ConfigProcessor : Loading config from cache: C:\Users\homebrew\AppData\Local\Temp\b6a0c3fa509e03dd7943cf1395b72ece.mpf_cache
2025-03-26 10:46:28,159 : INFO : ConfigProcessor : Loading config from cache: C:\Users\homebrew\AppData\Local\Temp\d18a920afddb781d4f34b36ac5cb2e09.mpf_cache
2025-03-26 10:46:28,159 : INFO : ConfigProcessor : Loading config from cache: C:\Users\homebrew\AppData\Local\Temp\50de7258194ae9293cbe8c4fce9577e7.mpf_cache
2025-03-26 10:46:28,159 : INFO : ConfigProcessor : Loading config from cache: C:\Users\homebrew\AppData\Local\Temp\2a76f107a833b8953199c5c910a26856.mpf_cache
2025-03-26 10:46:28,159 : INFO : ConfigProcessor : Loading config from cache: C:\Users\homebrew\AppData\Local\Temp\529fba7289b2d9f945cd5a4488c8b5fa.mpf_cache
2025-03-26 10:46:28,159 : INFO : ConfigProcessor : Loading config from cache: C:\Users\homebrew\AppData\Local\Temp\8c97cf9697840e2ca000923ba54f1b48.mpf_cache
2025-03-26 10:46:28,159 : INFO : ConfigProcessor : Loading config from cache: C:\Users\homebrew\AppData\Local\Temp\e8cb3f2c2e9a26851ec893c5156e3f7c.mpf_cache
2025-03-26 10:46:28,159 : INFO : ConfigProcessor : Loading config from cache: C:\Users\homebrew\AppData\Local\Temp\78a1fb055772b356de30948f28682ed0.mpf_cache
2025-03-26 10:46:28,159 : INFO : ConfigProcessor : Loading config from cache: C:\Users\homebrew\AppData\Local\Temp\67cfb29d96313268f86362bebab46239.mpf_cache
2025-03-26 10:46:28,168 : INFO : Machine : Mission Pinball Framework Core Engine v0.80.0.dev4
2025-03-26 10:46:28,168 : INFO : Machine : Command line arguments: {'no_load_cache': False, 'create_config_cache': True, 'bcp': True, 'configfile': ['config.yaml'], 'force_assets_load': False, 'platform_integration_test': False, 'jsonlogging': False, 'logfile': 'logs\\2025-03-26-10-46-28-mpf-mpf.log', 'pause': False, 'production': False, 'text_ui': True, 'loglevel': 15, 'consoleloglevel': 20, 'force_platform': None, 'syslog_address': None, 'mc_file_name': None, 'no_sound': False, 'full_logfile_path': 'C:\\Users\\homebrew\\Desktop\\thing_pinball\\logs\\2025-03-26-10-46-28-mpf-mpf.log'}
2025-03-26 10:46:28,168 : INFO : Machine : MPF path: C:\Users\homebrew\AppData\Local\Programs\Python\Python312\Lib\site-packages\mpf
2025-03-26 10:46:28,168 : INFO : Machine : Machine path: C:\Users\homebrew\Desktop\thing_pinball
2025-03-26 10:46:28,168 : INFO : Machine : Platform: win32
2025-03-26 10:46:28,168 : INFO : Machine : Python executable location: C:\Users\homebrew\AppData\Local\Programs\Python\Python312\python.exe
2025-03-26 10:46:28,168 : INFO : Machine : Python version: 3.12.3 (64-bit)
2025-03-26 10:46:28,168 : INFO : Machine : Initializing MPF...
2025-03-26 10:46:28,405 : INFO : FAST [NET] : Trying to connect to com4 at 921600bps
2025-03-26 10:46:28,405 : ERROR : FAST [NET] : Failed to connect to any of the specified ports.
2025-03-26 10:46:28,405 : INFO : Machine : Shutting down...
2025-03-26 10:46:28,405 : INFO : EventManager : Event: ======'shutdown'====== Args={}
2025-03-26 10:46:28,518 : ERROR : Machine : Failed to initialize MPF
Traceback (most recent call last):
  File "C:\Users\homebrew\AppData\Local\Programs\Python\Python312\Lib\site-packages\mpf\platforms\fast\fast.py", line 277, in _connect_to_hardware
    await communicator.connect()
  File "C:\Users\homebrew\AppData\Local\Programs\Python\Python312\Lib\site-packages\mpf\platforms\fast\communicators\base.py", line 114, in connect
    raise SerialException(f"{self} could not connect to a serial port. Is it open in CoolTerm? ;)")
serial.serialutil.SerialException: [FAST NET] could not connect to a serial port. Is it open in CoolTerm? ;)

The above exception was the direct cause of the following exception:

Traceback (most recent call last):
  File "C:\Users\homebrew\AppData\Local\Programs\Python\Python312\Lib\site-packages\mpf\core\machine.py", line 675, in initialize_mpf
    raise init.exception()
  File "C:\Users\homebrew\AppData\Local\Programs\Python\Python312\Lib\site-packages\mpf\core\machine.py", line 247, in initialize
    await self.initialize_core_and_hardware()
  File "C:\Users\homebrew\AppData\Local\Programs\Python\Python312\Lib\site-packages\mpf\core\machine.py", line 243, in initialize_core_and_hardware
    await self._initialize_platforms()
  File "C:\Users\homebrew\AppData\Local\Programs\Python\Python312\Lib\site-packages\mpf\core\machine.py", line 333, in _initialize_platforms
    result.result()
  File "C:\Users\homebrew\AppData\Local\Programs\Python\Python312\Lib\site-packages\mpf\platforms\fast\fast.py", line 123, in initialize
    await self._connect_to_hardware()
  File "C:\Users\homebrew\AppData\Local\Programs\Python\Python312\Lib\site-packages\mpf\platforms\fast\fast.py", line 284, in _connect_to_hardware
    raise MpfRuntimeError(f"Could not open serial port {port}. Is something else connected to the port? "
mpf.exceptions.runtime_error.MpfRuntimeError: Runtime Error in FAST: Could not open serial port net. Is something else connected to the port? Did the port number or your computer change? Do you have permissions to access the port? Error Code: RE-FAST-1 (https://missionpinball.org/logs)
2025-03-26 10:46:28,549 : INFO : root : MPF run loop ended.
